Workbook

Sheet Dashboard
B1: NETFLIX CONTENT INSIGHTS DASHBOARD
B3: Auspify Data Science Internship | Task 6 – Business Insights | Netflix Titles Dataset (8,790 titles, release years 1925–2021)
B5: TOTAL TITLES | E5: MOVIES | H5: TV SHOWS | K5: RELEASE SPAN | N5: AVG MOVIE LENGTH | Q5: MOST COMMON RATING
B6: =Data_Summary!B7 -> 8790 | E6: =Data_Summary!B5 -> 6126 | H6: =Data_Summary!B6 -> 2664 | K6: =MIN(Data_Yearly!A5:A78)&"–"&MAX(Data_Yearly!A5:A78) -> 1925–2021 | N6: =Data_Summary!B50 -> 99.584884 | Q6: =INDEX(Data_Summary!$A$37:$A$46,MATCH(MAX(Data_Summary!$B$37:$B$46),Data_Summary!$B$37:$B$46,0)) -> TV-MA
B8: ="catalog size" -> catalog size | E8: =TEXT(Data_Summary!C5,"0.0%")&" of catalog" -> 69.7% of catalog | H8: =TEXT(Data_Summary!C6,"0.0%")&" of catalog" -> 30.3% of catalog | K8: =COUNT(Data_Yearly!A5:A78)&" distinct release years" -> 74 distinct release years | N8: ="median "&Data_Summary!B54&" min" -> median 98 min | Q8: =TEXT(MAX(Data_Summary!C37:C46),"0.0%")&" of titles" -> 36.5% of titles

Sheet Data_Yearly
A1: Titles Released per Year
A4: Release Year | B4: Movies | C4: TV Shows | D4: Total Titles | E4: % of Catalog
A5: 1925 | B5: 0 | C5: 1 | D5: =B5+C5 -> 1 | E5: =D5/$D$79 -> 0.00011376564
A6: 1942 | B6: 2 | C6: 0 | D6: =B6+C6 -> 2 | E6: =D6/$D$79 -> 0.00022753129
A7: 1943 | B7: 3 | C7: 0 | D7: =B7+C7 -> 3 | E7: =D7/$D$79 -> 0.00034129693
A8: 1944 | B8: 3 | C8: 0 | D8: =B8+C8 -> 3 | E8: =D8/$D$79 -> 0.00034129693
A9: 1945 | B9: 3 | C9: 1 | D9: =B9+C9 -> 4 | E9: =D9/$D$79 -> 0.00045506257
A10: 1946 | B10: 1 | C10: 1 | D10: =B10+C10 -> 2 | E10: =D10/$D$79 -> 0.00022753129
A11: 1947 | B11: 1 | C11: 0 | D11: =B11+C11 -> 1 | E11: =D11/$D$79 -> 0.00011376564
A12: 1954 | B12: 2 | C12: 0 | D12: =B12+C12 -> 2 | E12: =D12/$D$79 -> 0.00022753129
A13: 1955 | B13: 3 | C13: 0 | D13: =B13+C13 -> 3 | E13: =D13/$D$79 -> 0.00034129693
A14: 1956 | B14: 2 | C14: 0 | D14: =B14+C14 -> 2 | E14: =D14/$D$79 -> 0.00022753129
A15: 1958 | B15: 3 | C15: 0 | D15: =B15+C15 -> 3 | E15: =D15/$D$79 -> 0.00034129693
A16: 1959 | B16: 1 | C16: 0 | D16: =B16+C16 -> 1 | E16: =D16/$D$79 -> 0.00011376564
... A78: 2021 | B78: 277 | C78: 315 | D78: =B78+C78 -> 592 | E78: =D78/$D$79 -> 0.067349261
A79: Total | B79: =SUM(B5:B78) -> 6126 | C79: =SUM(C5:C78) -> 2664 | D79: =SUM(D5:D78) -> 8790 | E79: =SUM(E5:E78) -> 1

Sheet Data_Summary
A1: Catalog Summary Tables
A3: Content Type
A4: Type | B4: Titles | C4: % of Catalog
A5: Movie | B5: 6126 | C5: =B5/$B$7 -> 0.69692833
A6: TV Show | B6: 2664 | C6: =B6/$B$7 -> 0.30307167
A7: Total | B7: =SUM(B5:B6) -> 8790 | C7: =SUM(C5:C6) -> 1
A9: Top Countries (by title count)
A10: Country | B10: Titles | C10: % of Catalog
A11: United States | B11: 3240 | C11: =B11/$B$7 -> 0.36860068
A12: India | B12: 1057 | C12: =B12/$B$7 -> 0.12025028
A13: United Kingdom | B13: 638 | C13: =B13/$B$7 -> 0.07258248
A14: Pakistan | B14: 421 | C14: =B14/$B$7 -> 0.047895336
A15: Canada | B15: 271 | C15: =B15/$B$7 -> 0.030830489
A16: Japan | B16: 259 | C16: =B16/$B$7 -> 0.029465301
A17: South Korea | B17: 214 | C17: =B17/$B$7 -> 0.024345848
A18: France | B18: 213 | C18: =B18/$B$7 -> 0.024232082
A19: Spain | B19: 182 | C19: =B19/$B$7 -> 0.020705347
A22: Top Genres (by title count)
A23: Genre | B23: Titles | C23: % of Catalog
A24: International Movies | B24: 2752 | C24: =B24/$B$7 -> 0.31308305
A25: Dramas | B25: 2426 | C25: =B25/$B$7 -> 0.27599545
A26: Comedies | B26: 1674 | C26: =B26/$B$7 -> 0.19044369
A27: International TV Shows | B27: 1349 | C27: =B27/$B$7 -> 0.15346985
A28: Documentaries | B28: 869 | C28: =B28/$B$7 -> 0.098862344
A29: Action & Adventure | B29: 859 | C29: =B29/$B$7 -> 0.097724687
A30: TV Dramas | B30: 762 | C30: =B30/$B$7 -> 0.08668942
A31: Independent Movies | B31: 756 | C31: =B31/$B$7 -> 0.086006826
A32: Children & Family Movies | B32: 641 | C32: =B32/$B$7 -> 0.072923777
A33: Romantic Movies | B33: 616 | C33: =B33/$B$7 -> 0.070079636
A35: Content Ratings (Top 10)
A36: Rating | B36: Titles | C36: % of Catalog
A37: TV-MA | B37: 3205 | C37: =B37/$B$7 -> 0.36461889
A38: TV-14 | B38: 2157 | C38: =B38/$B$7 -> 0.24539249
A39: TV-PG | B39: 861 | C39: =B39/$B$7 -> 0.097952218
A40: R | B40: 799 | C40: =B40/$B$7 -> 0.090898749
A41: PG-13 | B41: 490 | C41: =B41/$B$7 -> 0.055745165
A42: TV-Y7 | B42: 333 | C42: =B42/$B$7 -> 0.037883959
A43: TV-Y | B43: 306 | C43: =B43/$B$7 -> 0.034812287
A44: PG | B44: 287 | C44: =B44/$B$7 -> 0.032650739
A45: TV-G | B45: 220 | C45: =B45/$B$7 -> 0.025028441
...

Sheet Forecast
A1: Trend Forecast – Linear Regression
A2: Replicates Task 4: 80/20 time-ordered split for evaluation; model refit on all years for the 2022–2026 forecast.
A4: Year | B4: Actual Titles | C4: Linear Trend (fit) | D4: Hold-out Prediction | F4: Model Parameters
A5: =Data_Yearly!A5 -> 1925 | B5: =Data_Yearly!D5 -> 1 | C5: =FORECAST(A5,$B$5:$B$78,$A$5:$A$78) -> -283.73625 | F5: Item | G5: Value
A6: =Data_Yearly!A6 -> 1942 | B6: =Data_Yearly!D6 -> 2 | C6: =FORECAST(A6,$B$5:$B$78,$A$5:$A$78) -> -166.92651 | F6: Train period | G6: =A5&"–"&A63 -> 1925–2006
A7: =Data_Yearly!A7 -> 1943 | B7: =Data_Yearly!D7 -> 3 | C7: =FORECAST(A7,$B$5:$B$78,$A$5:$A$78) -> -160.05535 | F7: Test period | G7: =A64&"–"&A78 -> 2007–2021
A8: =Data_Yearly!A8 -> 1944 | B8: =Data_Yearly!D8 -> 3 | C8: =FORECAST(A8,$B$5:$B$78,$A$5:$A$78) -> -153.18419 | F8: Train / test records | G8: =COUNT(B5:B63)&" / "&COUNT(B64:B78) -> 59 / 15
A9: =Data_Yearly!A9 -> 1945 | B9: =Data_Yearly!D9 -> 4 | C9: =FORECAST(A9,$B$5:$B$78,$A$5:$A$78) -> -146.31303 | F9: Train slope (titles per year) | G9: =SLOPE(B5:B63,A5:A63) -> 0.80830776
A10: =Data_Yearly!A10 -> 1946 | B10: =Data_Yearly!D10 -> 2 | C10: =FORECAST(A10,$B$5:$B$78,$A$5:$A$78) -> -139.44187 | F10: Train intercept | G10: =INTERCEPT(B5:B63,A5:A63) -> -1580.8725
A11: =Data_Yearly!A11 -> 1947 | B11: =Data_Yearly!D11 -> 1 | C11: =FORECAST(A11,$B$5:$B$78,$A$5:$A$78) -> -132.57071
A12: =Data_Yearly!A12 -> 1954 | B12: =Data_Yearly!D12 -> 2 | C12: =FORECAST(A12,$B$5:$B$78,$A$5:$A$78) -> -84.472582 | F12: Hold-out Evaluation
A13: =Data_Yearly!A13 -> 1955 | B13: =Data_Yearly!D13 -> 3 | C13: =FORECAST(A13,$B$5:$B$78,$A$5:$A$78) -> -77.601421 | F13: Metric | G13: Value
A14: =Data_Yearly!A14 -> 1956 | B14: =Data_Yearly!D14 -> 2 | C14: =FORECAST(A14,$B$5:$B$78,$A$5:$A$78) -> -70.73026 | F14: MAE | G14: =SUMPRODUCT(ABS(B64:B78-D64:D78))/COUNT(B64:B78) -> 475.14067
A15: =Data_Yearly!A15 -> 1958 | B15: =Data_Yearly!D15 -> 3 | C15: =FORECAST(A15,$B$5:$B$78,$A$5:$A$78) -> -56.987939 | F15: RMSE | G15: =SQRT(SUMPRODUCT((B64:B78-D64:D78)^2)/COUNT(B64:B78)) -> 603.20015
A16: =Data_Yearly!A16 -> 1959 | B16: =Data_Yearly!D16 -> 1 | C16: =FORECAST(A16,$B$5:$B$78,$A$5:$A$78) -> -50.116778 | F16: R² Score | G16: =1-SUMPRODUCT((B64:B78-D64:D78)^2)/SUMPRODUCT((B64:B78-AVERAGE(B64:B78))^2) -> -1.5930289
A17: =Data_Yearly!A17 -> 1960 | B17: =Data_Yearly!D17 -> 4 | C17: =FORECAST(A17,$B$5:$B$78,$A$5:$A$78) -> -43.245617
A18: =Data_Yearly!A18 -> 1961 | B18: =Data_Yearly!D18 -> 1 | C18: =FORECAST(A18,$B$5:$B$78,$A$5:$A$78) -> -36.374456 | F18: Forecast (model refit on all years)
A19: =Data_Yearly!A19 -> 1962 | B19: =Data_Yearly!D19 -> 3 | C19: =FORECAST(A19,$B$5:$B$78,$A$5:$A$78) -> -29.503295 | F19: Year | G19: Predicted Titles
A20: =Data_Yearly!A20 -> 1963 | B20: =Data_Yearly!D20 -> 2 | C20: =FORECAST(A20,$B$5:$B$78,$A$5:$A$78) -> -22.632135 | F20: =A79 -> 2022 | G20: =ROUND(C79,0) -> 383
A21: =Data_Yearly!A21 -> 1964 | B21: =Data_Yearly!D21 -> 2 | C21: =FORECAST(A21,$B$5:$B$78,$A$5:$A$78) -> -15.760974 | F21: =A80 -> 2023 | G21: =ROUND(C80,0) -> 390
A22: =Data_Yearly!A22 -> 1965 | B22: =Data_Yearly!D22 -> 2 | C22: =FORECAST(A22,$B$5:$B$78,$A$5:$A$78) -> -8.8898128 | F22: =A81 -> 2024 | G22: =ROUND(C81,0) -> 397
A23: =Data_Yearly!A23 -> 1966 | B23: =Data_Yearly!D23 -> 1 | C23: =FORECAST(A23,$B$5:$B$78,$A$5:$A$78) -> -2.018652 | F23: =A82 -> 2025 | G23: =ROUND(C82,0) -> 403
A24: =Data_Yearly!A24 -> 1967 | B24: =Data_Yearly!D24 -> 5 | C24: =FORECAST(A24,$B$5:$B$78,$A$5:$A$78) -> 4.8525088 | F24: =A83 -> 2026 | G24: =ROUND(C83,0) -> 410
A25: =Data_Yearly!A25 -> 1968 | B25: =Data_Yearly!D25 -> 3 | C25: =FORECAST(A25,$B$5:$B$78,$A$5:$A$78) -> 11.72367
A26: =Data_Yearly!A26 -> 1969 | B26: =Data_Yearly!D26 -> 2 | C26: =FORECAST(A26,$B$5:$B$78,$A$5:$A$78) -> 18.59483
A27: =Data_Yearly!A27 -> 1970 | B27: =Data_Yearly!D27 -> 2 | C27: =FORECAST(A27,$B$5:$B$78,$A$5:$A$78) -> 25.465991
A28: =Data_Yearly!A28 -> 1971 | B28: =Data_Yearly!D28 -> 5 | C28: =FORECAST(A28,$B$5:$B$78,$A$5:$A$78) -> 32.337152
A29: =Data_Yearly!A29 -> 1972 | B29: =Data_Yearly!D29 -> 5 | C29: =FORECAST(A29,$B$5:$B$78,$A$5:$A$78) -> 39.208313
A30: =Data_Yearly!A30 -> 1973 | B30: =Data_Yearly!D30 -> 10 | C30: =FORECAST(A30,$B$5:$B$78,$A$5:$A$78) -> 46.079474
A31: =Data_Yearly!A31 -> 1974 | B31: =Data_Yearly!D31 -> 7 | C31: =FORECAST(A31,$B$5:$B$78,$A$5:$A$78) -> 52.950635
A32: =Data_Yearly!A32 -> 1975 | B32: =Data_Yearly!D32 -> 7 | C32: =FORECAST(A32,$B$5:$B$78,$A$5:$A$78) -> 59.821796
A33: =Data_Yearly!A33 -> 1976 | B33: =Data_Yearly!D33 -> 9 | C33: =FORECAST(A33,$B$5:$B$78,$A$5:$A$78) -> 66.692956
A34: =Data_Yearly!A34 -> 1977 | B34: =Data_Yearly!D34 -> 7 | C34: =FORECAST(A34,$B$5:$B$78,$A$5:$A$78) -> 73.564117
A35: =Data_Yearly!A35 -> 1978 | B35: =Data_Yearly!D35 -> 7 | C35: =FORECAST(A35,$B$5:$B$78,$A$5:$A$78) -> 80.435278
A36: =Data_Yearly!A36 -> 1979 | B36: =Data_Yearly!D36 -> 11 | C36: =FORECAST(A36,$B$5:$B$78,$A$5:$A$78) -> 87.306439
... A63: =Data_Yearly!A63 -> 2006 | B63: =Data_Yearly!D63 -> 96 | C63: =FORECAST(A63,$B$5:$B$78,$A$5:$A$78) -> 272.82778
A64: =Data_Yearly!A64 -> 2007 | B64: =Data_Yearly!D64 -> 88 | C64: =FORECAST(A64,$B$5:$B$78,$A$5:$A$78) -> 279.69894 | D64: =$G$9*A64+$G$10 -> 41.401181
A65: =Data_Yearly!A65 -> 2008 | B65: =Data_Yearly!D65 -> 135 | C65: =FORECAST(A65,$B$5:$B$78,$A$5:$A$78) -> 286.5701 | D65: =$G$9*A65+$G$10 -> 42.209488
A66: =Data_Yearly!A66 -> 2009 | B66: =Data_Yearly!D66 -> 152 | C66: =FORECAST(A66,$B$5:$B$78,$A$5:$A$78) -> 293.44126 | D66: =$G$9*A66+$G$10 -> 43.017796
A67: =Data_Yearly!A67 -> 2010 | B67: =Data_Yearly!D67 -> 192 | C67: =FORECAST(A67,$B$5:$B$78,$A$5:$A$78) -> 300.31242 | D67: =$G$9*A67+$G$10 -> 43.826104
...
